# This file is auto-generated by the dh-umc tools and should not be edited!
msgid ""
msgstr ""
"Project-Id-Version: univention-management-console-module-diagnostic\n"
"Report-Msgid-Bugs-To: packages@univention.de\n"
"POT-Creation-Date: 2017-09-19 15:36+0200\n"
"PO-Revision-Date: \n"
"Last-Translator: Univention GmbH <packages@univention.de>\n"
"Language-Team: Univention GmbH <packages@univention.de>\n"
"Language: de\n"
"MIME-Version: 1.0\n"
"Content-Type: text/plain; charset=UTF-8\n"
"Content-Transfer-Encoding: 8bit\n"

#: umc/python/diagnostic/plugins/21_check_join_status.py:54
msgid ""
"\"univention-check-join-status\" returned a problem with the domain join."
msgstr ""
"\"univention-check-join-status\" gab einen Fehler mit dem Domänenbeitritt "
"zurück."

#: umc/python/diagnostic/plugins/11_nameserver.py:15
#, python-format
msgid "%d of the configured nameservers are not responding to DNS queries."
msgstr "%d der konfigurierten Nameserver anworten nicht auf DNS-Anfragen."

#: umc/python/diagnostic/plugins/30_disk_usage.py:120
#, python-format
msgid "- Disk for mountpoint %(mp)s is %(pc)s%% full."
msgstr "- Festplatte für Moint Point %(mp)s ist %(pc)s%% voll."

#: umc/python/diagnostic/plugins/11_nameserver.py:46
msgid "A timeout occurred while reaching the nameserver (is it online?)."
msgstr ""
"Eine Zeitüberschreitung trat beim Erreichen des Nameservers auf (ist er "
"online?)."

#: umc/python/diagnostic/plugins/52_mail_acl_sync.py:100
msgid "ACL right for group {id!r} is {udm!r} in UDM, but {imap!r} in IMAP."
msgstr ""
"ACL Berechtigung für die Gruppe {id!r} ist {udm!r} in UDM, aber {imap!r} in "
"IMAP."

#: umc/python/diagnostic/plugins/52_mail_acl_sync.py:94
msgid "ACL right for user {id!r} is {udm!r} in UDM, but {imap!r} in IMAP."
msgstr ""
"ACL Berechtigung für den Nutzer {id!r} ist {udm!r} in UDM, aber {imap!r} in "
"IMAP."

#: umc/python/diagnostic/plugins/22_kdc_service.py:332
msgid "Add lo to samba/interfaces"
msgstr "Füge lo zu samba/interfaces hinzu"

#: umc/python/diagnostic/plugins/32_security_limits.py:31
msgid "Adjust to suggested limits"
msgstr "An vorgeschlagene Limits anpassen"

#: umc/python/diagnostic/plugins/44_well_known_sid_check.py:47
msgid "All SIDs exist and names are consistent."
msgstr "Alle SIDs existieren und die Namen sind konsistent."

#: umc/python/diagnostic/plugins/02_certificate_check.py:53
msgid "All SSL certificates valid."
msgstr "Alle SSL Zertifikate sind gültig."

#: umc/python/diagnostic/plugins/31_file_permissions.py:47
#: umc/python/diagnostic/plugins/54_sources_list_check.py:44
msgid "All files ok."
msgstr "Alle Dateien in Ordnung."

#: umc/python/diagnostic/plugins/20_check_nameservers.py:49
msgid "All nameserver entries are ok."
msgstr "Alle Nameserver Einträge sind in Ordnung."

#: umc/python/diagnostic/plugins/52_mail_acl_sync.py:50
msgid "All shared folder ACLs are in sync with UDM."
msgstr "Alle ACL Einträge der globalen IMAP Ordner stimmen mit UDM überein."

#: umc/python/diagnostic/plugins/00_check_server_password.py:150
msgid "Authentication against the local LDAP failed with the machine password."
msgstr ""
"Authentifizierung gegen das lokale LDAP mit dem Password für das "
"Rechnerkonto ist fehlgeschlagen."

#: umc/python/diagnostic/plugins/00_check_server_password.py:154
msgid ""
"Authentication against the master LDAP failed with the machine password."
msgstr ""
"Authentifizierung gegen das Master LDAP mit dem Password für das "
"Rechnerkonto ist fehlgeschlagen."

#: umc/python/diagnostic/plugins/00_check_server_password.py:53
msgid "Authentication with machine password against LDAP successful."
msgstr "Authentifizierung mit dem Password für das Rechnerkonto erfolgreich."

#: umc/python/diagnostic/plugins/00_check_server_password.py:111
msgid "Calling /usr/lib/univention-server/server_password_change failed."
msgstr ""
"Aufruf von /usr/lib/univention-server/server_password_change ist "
"fehlgeschlagen."

#: umc/python/diagnostic/plugins/02_certificate_check.py:76
msgid "Certificate {path!r} will expire in {days} days."
msgstr "Zertifikat {path!r} wird in {days} Tagen ablaufen."

#: umc/python/diagnostic/plugins/45_heimdal_on_samba4_dc.py:45
msgid "Check Heimdal KDC on Samba 4 DC"
msgstr "Überprüfe Heimdal KDC auf Samba 4 DC"

#: umc/python/diagnostic/plugins/52_mail_acl_sync.py:49
msgid "Check IMAP shared folder ACLs"
msgstr "Überprüfe ACL Einträge der globalen IMAP Ordner"

#: umc/python/diagnostic/plugins/41_samba_tool_showrepl.py:53
msgid "Check Samba replication status for errors"
msgstr "Überprüfe den Samba Replikations Status"

#: umc/python/diagnostic/plugins/42_samba_tool_sysvolcheck.py:40
msgid "Check Samba sysvol ACLs for errors"
msgstr "Überprüfe die Samba SYSVOL ACL Einträge auf Fehler"

#: umc/python/diagnostic/plugins/54_sources_list_check.py:43
msgid "Check errors in sources.list files"
msgstr "Überprüfe Fehler in den sources.list Dateien"

#: umc/python/diagnostic/plugins/31_file_permissions.py:46
msgid "Check file permissions"
msgstr "Überprüfe Datei Berechtigungen"

#: umc/python/diagnostic/plugins/50_check_ucr_templates.py:41
msgid "Check for modified UCR templates"
msgstr "Überprüfe veränderte UCR Vorlagen"

#: umc/python/diagnostic/plugins/03_check_notifier_replication.py:42
msgid "Check for problems with UDN replication"
msgstr "Überprüfe Probleme mit der UDN Replikation"

#: umc/python/diagnostic/plugins/30_disk_usage.py:42
msgid "Check free disk space"
msgstr "Überprüfe freien Festplatten Platz"

#: umc/python/diagnostic/plugins/51_hostname_check.py:42
msgid "Check hostname RFC compliance"
msgstr "Überprüfe Rechnernamen auf RFC Konformität"

#: umc/python/diagnostic/plugins/21_check_join_status.py:40
msgid "Check join status"
msgstr "Überprüfe den Zustand des Domänenbeitritts"

#: umc/python/diagnostic/plugins/46_kerberos_ddns_update.py:45
msgid "Check kerberos authenticated DNS updates"
msgstr "Überprüfe Kerberos authentifizierte DNS Updates"

#: umc/python/diagnostic/plugins/40_samba_tool_dbcheck.py:40
msgid "Check local AD database for errors"
msgstr "Teste die lokale AD Datenbank auf Fehler"

#: umc/python/diagnostic/plugins/00_check_server_password.py:52
msgid "Check machine password"
msgstr "Password für das Rechnerkonto testen"

#: umc/python/diagnostic/plugins/20_check_nameservers.py:48
msgid "Check nameserver entries on DNS zones"
msgstr "Überprüfe die Nameserver Einträge der DNS Zonen"

#: umc/python/diagnostic/plugins/23_check_update_sites.py:43
msgid "Check resolving repository servers"
msgstr "Überprüfe DNS Auflösung der Repository Server"

#: umc/python/diagnostic/plugins/02_certificate_check.py:52
msgid "Check validity of SSL certificates"
msgstr "Überprüfe Gültigkeit der SSL Zertifikate"

#: umc/python/diagnostic/plugins/44_well_known_sid_check.py:46
msgid "Check well known SIDs"
msgstr "Überprüfe 'Well Known' SIDs"

#: umc/python/diagnostic/plugins/30_disk_usage.py:43
msgid "Enough free disk space available."
msgstr "Außreichend freier Festplatten Platz vorhanden."

#: umc/python/diagnostic/plugins/03_check_notifier_replication.py:72
msgid "Error retrieving notifier ID from the UDN."
msgstr "Fehler beim Abrufen der letzten Transaktions ID vom UDN."

#: umc/python/diagnostic/plugins/50_check_ucr_templates.py:51
msgid "Errors found by `univention-check-templates`."
msgstr "Es wurden Fehler durch `univention-check-templates` gefunden."

#: umc/python/diagnostic/plugins/46_kerberos_ddns_update.py:147
msgid "Errors occured while running `kinit` or `nsupdate`."
msgstr "Fehler traten auf bei der Ausführung von `kinit` oder `nsupdate`."

#: umc/python/diagnostic/plugins/31_file_permissions.py:57
msgid "File {path!r} does not exist."
msgstr "Datei {path!r} existiert nicht."

#: umc/python/diagnostic/plugins/31_file_permissions.py:80
msgid "File {path!r} has mode {actual:o}, {expected:o} was expected."
msgstr "Datei {path!r} hat Datei-Modus {actual:o}, {expected:o} war erwartet."

#: umc/python/diagnostic/plugins/31_file_permissions.py:67
msgid "File {path!r} has owner {actual!r} while {expected!r} was expected."
msgstr ""
"Datei {path!r} hat den Besitzer {actual!r}, während {expected!r} erwartet "
"war."

#: umc/python/diagnostic/plugins/00_check_server_password.py:145
msgid "Fix machine password"
msgstr "Korrigiere Password für das Rechnerkonto"

#: umc/python/diagnostic/plugins/52_mail_acl_sync.py:305
msgid ""
"Found differences in the ACLs for IMAP shared folders between UDM and IMAP."
msgstr ""
"Es wurde ein Unterschied in den ACL Einträge für die globalen IMAP Ordner "
"zwischen UDM und IMAP gefunden."

#: umc/python/diagnostic/plugins/20_check_nameservers.py:215
msgid "Found errors in the nameserver entries of the following zones."
msgstr ""
"Es wurden Fehler in den Nameserver Einträgen der folgenden Zonen gefunden."

#: umc/python/diagnostic/plugins/54_sources_list_check.py:75
msgid "Found exception in {path!r}: {exception}"
msgstr "Fehler in {path!r} gefunden: {exception}"

#: umc/python/diagnostic/plugins/02_certificate_check.py:93
msgid "Found expired certificate {path!r}."
msgstr "Abgelaufenes Zertifikat {path!r} gefunden."

#: umc/python/diagnostic/plugins/20_check_nameservers.py:78
#, python-brace-format
msgid "Found illegal alias record (CNAME record) for nameserver {ns}."
msgstr "Ungültiger Alias-Record (CNAME record) für Namenserver {ns} gefunden."

#: umc/python/diagnostic/plugins/02_certificate_check.py:106
msgid "Found invalid certificate {path!r}."
msgstr "Ungültiges Zertifikat {path!r} gefunden."

#: umc/python/diagnostic/plugins/02_certificate_check.py:104
msgid ""
"Found invalid certificate {path!r}:\n"
"{message}"
msgstr ""
"Ungültiges Zertifikat {path!r} gefunden:\n"
"{message}"

#: umc/python/diagnostic/plugins/02_certificate_check.py:115
msgid "Found malformed certificate {path!r}."
msgstr "Korruptes Zertifikat {path!r} gefunden."

#: umc/python/diagnostic/plugins/20_check_nameservers.py:72
#, python-brace-format
msgid "Found no host record (A/AAAA record) for nameserver {ns}."
msgstr "Kein Host-Record (A/AAAA record) für Namenserver {ns} gefunden."

#: umc/python/diagnostic/plugins/02_certificate_check.py:87
msgid "Found not yet valid certificate {path!r}."
msgstr "Noch nicht gültiges Zertifikat {path!r} gefunden."

#: umc/python/diagnostic/plugins/43_connectors4_rejects.py:141
#, python-brace-format
msgid ""
"Found {ucs} UCS rejects and {s4} S4 rejects. See {{sdb}} for more "
"information."
msgstr ""
"{ucs} nicht synchronisierte UCS Objekte und {s4} nicht synchronisierte S4 "
"Objekte. Weitere Hinweise finden Sie unter {{sdb}}."

#: umc/python/diagnostic/plugins/10_gateway.py:11
msgid "Gateway is not reachable"
msgstr "Gateway ist nicht erreichbar"

#: umc/python/diagnostic/plugins/01_ssh_connection.py:54
msgid "Host key for server does not match"
msgstr "SSH Host-Key des Servers stimmt nicht überein"

#: umc/python/diagnostic/plugins/11_nameserver.py:17
msgid ""
"If the problem persists make sure the nameserver is connected to the network "
"and the forwarders are able to reach the internet (www.univention.de)."
msgstr ""
"Falls das Problem bestehen bleibt stellen Sie sicher, dass der Nameserver "
"mit dem Netzwerk verbunden ist und die DNS-Forwarder das Internet erreichen "
"können (www.univention.de)."

#: umc/python/diagnostic/plugins/10_gateway.py:14
msgid "If these settings are correct the problem relies in the gateway itself:"
msgstr ""
"Wenn diese Einstellungen richtig sind liegt das Problem im Gateway selbst:"

#: umc/python/diagnostic/plugins/20_check_nameservers.py:218
#, python-brace-format
msgid "In forward zone {name} (see {{{link}}}):"
msgstr "In der Forward-Zone {name} (siehe {{{link}}}):"

#: umc/python/diagnostic/plugins/52_mail_acl_sync.py:312
#, python-brace-format
msgid "In mail folder {name} (see {{udm:mail/mail}}):"
msgstr "Im globalen Mail Ordner {name} (siehe {{udm:mail/mail}}):"

#: umc/python/diagnostic/plugins/20_check_nameservers.py:219
#, python-brace-format
msgid "In reverse zone {name} (see {{{link}}}):"
msgstr "In der Reverse-Zone {name} (siehe {{{link}}}):"

#: umc/python/diagnostic/plugins/41_samba_tool_showrepl.py:130
msgid "Inbound {nc!r}: error during DRS replication from {source} ({estring})"
msgstr ""
"In eingehend {nc!r}: Fehler während der DRS Replikation von {source} "
"({estring})."

#: umc/python/diagnostic/plugins/32_security_limits.py:19
#, python-brace-format
msgid ""
"It is suggested to increase the security limits either manually by using "
"{ucr} or to automatically adjust them to the suggested limits:"
msgstr ""
"Es ist empfohlen, die Sicherheitslimits entweder manuell durch benutzen des "
"{ucr} oder durch automatische Anpassung auf die empfohlenen Limits zu "
"erhöhen."

#: umc/python/diagnostic/plugins/22_kdc_service.py:58
msgid "KDC service check"
msgstr "KDC Erreichbarkeit"

#: umc/python/diagnostic/plugins/55_user_migration.py:13
msgid ""
"With UCS 4.3 the LDAP format of user objects changed. After upgrading the "
"domaincontroller master all user objects are migrated into the new format."
msgstr ""
"Mit UCS 4.3 hat sich das LDAP format von Nutzer Objekten geändert. "
"Nach Upgrade des Domänencontroller Master werden all Nutzer Objekte "
"in das neue Format migriert."

#: umc/python/diagnostic/plugins/55_user_migration.py:14
msgid ""
"When a user object is created by a system which is not yet on UCS 4.3 it "
"will have the old format. These user objects need to migrated again."
msgstr ""
"Wenn ein Nutzer auf System erstellt wurde, welches noch nicht auf UCS 4.3 "
"ist, wird dieser im alten Format sein. Diese Nutzer Objekte müssen erneut "
"migriert werden."

#: umc/python/diagnostic/plugins/55_user_migration.py:11
msgid "User objects which are not migrated"
msgstr ""
"Noch nicht migrierte Nutzer Objekte"

#: umc/python/diagnostic/plugins/55_user_migration.py:35
#, python-format
msgid "The migration failed: %s"
msgstr "Die Migration schlug fehl: %s"

#: umc/python/diagnostic/plugins/55_user_migration.py:27
msgid "Migrate user objects"
msgstr "Migriere Nutzer Objekte"

#: umc/python/diagnostic/plugins/01_ssh_connection.py:59
#, python-format
msgid ""
"Login to the remote server with the uid %(uid)s and the password from /etc/"
"machine.secret failed. "
msgstr ""
"Der Login auf dem entfernten Rechner mit der uid %(uid)s und dem Passwort "
"aus /etc/machine.secret is fehlgeschlagen. "

#: umc/python/diagnostic/plugins/53_package_status.py:14
msgid ""
"Login to the system as root via ssh and run the command \"dpkg --configure -a"
"\" in order to correct the packages status."
msgstr ""
"Um den Paketstatus zu korrigieren loggen Sie sich am System per ssh als root "
"ein und führen Sie das Kommando \"dpkg --configure -a\" aus."

#: umc/python/diagnostic/plugins/01_ssh_connection.py:58
msgid "Machine authentication failed"
msgstr "Authentifizierung mit dem Maschinen-Konto ist fehlgeschlagen"

#: umc/python/diagnostic/plugins/52_mail_acl_sync.py:63
msgid "Mail folder {folder!r} does not exist in IMAP."
msgstr "Globaler IMAP Order {folder!r} existiert nicht in IMAP."

#: umc/python/diagnostic/plugins/10_gateway.py:15
msgid "Make sure the hardware of the gateway device is working properly."
msgstr ""
"Stellen Sie sicher, dass die Hardware des Gateway-Geräts korrekt "
"funktioniert."

#: umc/python/diagnostic/plugins/21_check_join_status.py:45
msgid "Manual: Analysis of listener/notifier problems"
msgstr "Handbuch: Analyse von Listener/Notifier-Problemen"

#: umc/python/diagnostic/plugins/53_package_status.py:15
msgid ""
"More information about the cause can be gained by executing \"dpkg --audit\"."
msgstr ""
"Weitere Informationen über die Ursache können durch Ausführen von \"dpkg --"
"audit\" erhalten werden."

#: umc/python/diagnostic/plugins/52_mail_acl_sync.py:75
msgid "Multiple ACL entries for {id!r} in UDM."
msgstr "Mehrere ACL Einträge für {id!r} in UDM."

#: umc/python/diagnostic/plugins/11_nameserver.py:13
msgid "Nameserver(s) are not responsive"
msgstr "Nameserver sind nicht ansprechbar"

#: umc/python/diagnostic/plugins/43_connectors4_rejects.py:45
msgid "No S4 Connector rejects were found."
msgstr "Keine nicht synchronisierten S4 Connector Objekte gefunden."

#: umc/python/diagnostic/plugins/40_samba_tool_dbcheck.py:41
#: umc/python/diagnostic/plugins/41_samba_tool_showrepl.py:54
#: umc/python/diagnostic/plugins/42_samba_tool_sysvolcheck.py:41
msgid "No errors found."
msgstr "Keine Fehler gefunden."

#: umc/python/diagnostic/plugins/46_kerberos_ddns_update.py:46
msgid "No errors occured."
msgstr "Es traten keine Fehler auf."

#: umc/python/diagnostic/plugins/51_hostname_check.py:43
msgid "No non-compliant hostnames found."
msgstr "Keine nicht konformen Rechnernamen gefunden."

#: umc/python/diagnostic/plugins/03_check_notifier_replication.py:43
msgid "No problems found with UDN replication."
msgstr "Keine Prolbleme mit der UDN Replikation gefunden."

#: umc/python/diagnostic/plugins/50_check_ucr_templates.py:42
msgid "No problems found with modified UCR templates"
msgstr "Keine Probleme mit modifizierten UCR Vorlagen gefunden."

#: umc/python/diagnostic/plugins/23_check_update_sites.py:44
msgid "No problems were found while resolving update respositories."
msgstr "Es wurden keine Probleme beim Auflösen der Repository-Server gefunden."

#: umc/python/diagnostic/plugins/22_kdc_service.py:339
msgid "No reachable KDCs were found."
msgstr "Keine erreichbaren KDCs gefunden."

#: umc/python/diagnostic/plugins/44_well_known_sid_check.py:64
msgid "No user or group with SID {sid} found, expected {expected!r}."
msgstr ""
"Kein Nutzer oder keine Gruppe mit SID {sid} gefunden, {expected!r} war "
"erwartet."

#: umc/python/diagnostic/plugins/00_check_server_password.py:163
msgid ""
"Note that password rotation is disabled via the UCR variable server/password/"
"change."
msgstr ""
"Beachten Sie, dass die Passwordrotation durch die UCR Variable server/"
"password/change deaktiviert ist."

#: umc/python/diagnostic/plugins/00_check_server_password.py:164
msgid "Note that server/password/interval is set to {}."
msgstr "Beachten Sie, dass server/password/interval auf {} gesetzt ist."

#: umc/python/diagnostic/plugins/41_samba_tool_showrepl.py:138
msgid "Outbound {nc!r}: error during DRS replication to {source} ({estring})"
msgstr ""
"In ausgehend {nc!r}: Fehler während der DRS Replikation nach {source} "
"({estring})."

#: umc/python/diagnostic/plugins/53_package_status.py:11
msgid "Package status corrupt"
msgstr "Paketstatus korrupt"

#: umc/python/diagnostic/plugins/01_ssh_connection.py:60
msgid ""
"Please check /var/log/auth.log on the remote server for further information."
msgstr ""
"Bitte prüfen Sie /var/log/auth.log auf dem entfernten Rechner für weitere "
"Informationen."

#: umc/python/diagnostic/plugins/54_sources_list_check.py:101
msgid "Please check the files for more details."
msgstr "Überprüfen Sie die Dateien für mehr Details."

#: umc/python/diagnostic/plugins/11_nameserver.py:16
msgid ""
"Please make sure the DNS settings in the {setup:network} are correctly set "
"up."
msgstr ""
"Bitte sicherstellen, dass die DNS-Einstellungen in {setup:network} korrekt "
"konfiguriert sind."

#: umc/python/diagnostic/plugins/51_hostname_check.py:76
#, python-brace-format
msgid "Please refer to {rfc1123} for the syntax of host names."
msgstr "Siehe {rfc1123} für die Syntax von Rechnernamen."

#: umc/python/diagnostic/plugins/20_check_nameservers.py:216
#, python-brace-format
msgid "Please refer to {sdb} for further information."
msgstr "Siehe {sdb} für weitere Informationen."

#: umc/python/diagnostic/plugins/01_ssh_connection.py:56
#, python-format
msgid ""
"Please repair the host key of the remote server in /root/.ssh/known_hosts on "
"%(fqdn)s."
msgstr ""
"Der SSH Host-Key in /root/.ssh/known_hosts des entfernten Rechners muss auf "
"%(fqdn)s repariert werden."

#: umc/python/diagnostic/plugins/00_check_server_password.py:112
#, python-brace-format
msgid "Please see {sdb} for more information."
msgstr "Siehe {sdb} für weitere Informationen."

#: umc/python/diagnostic/plugins/23_check_update_sites.py:81
#, python-brace-format
msgid "Please see {sdb} for troubleshooting DNS problems."
msgstr "Siehe {sdb} für Problemhilfe bei DNS Problemen."

#: umc/python/diagnostic/plugins/02_certificate_check.py:296
#, python-brace-format
msgid "Please see {sdb} on how to renew certificates."
msgstr "Siehe {sdb} für Informationen zum Erneuern von Zertifikaten."

#: umc/python/diagnostic/plugins/12_proxy.py:15
msgid "Proxy server failure"
msgstr "Proxy-Server-Fehler"

#: umc/python/diagnostic/plugins/51_hostname_check.py:47
msgid "RFC 1123 - 2.1 Host Names and Numbers"
msgstr ""

#: umc/python/diagnostic/plugins/54_sources_list_check.py:97
msgid "Regenerate sources.list"
msgstr "Source-Listen neu generieren"

#: umc/python/diagnostic/plugins/22_kdc_service.py:335
msgid "Reset kerberos/kdc to 127.0.0.1"
msgstr "Setze kerberos/kdc auf 127.0.0.1 zurück"

#: umc/python/diagnostic/plugins/40_samba_tool_dbcheck.py:73
msgid "Run `samba-tool dbcheck --fix --cross-ncs --yes`"
msgstr "Führe `samba-tool dbcheck --fix --cross-ncs --yes` aus"

#: umc/python/diagnostic/plugins/42_samba_tool_sysvolcheck.py:73
msgid "Run `samba-tool ntacl sysvolreset`"
msgstr "Führe `samba-tool ntacl sysvolreset` aus"

#: umc/python/diagnostic/plugins/43_connectors4_rejects.py:44
msgid "S4 Connector rejects"
msgstr "Nicht synchronisierte S4 Connector Objekte"

#: umc/python/diagnostic/plugins/43_connectors4_rejects.py:155
#, python-brace-format
msgid "S4 DN: {s4}, UCS DN: {ucs}"
msgstr ""

#: umc/python/diagnostic/plugins/43_connectors4_rejects.py:152
msgid "S4 rejected:"
msgstr "Nicht synchronisierte S4 Objekte:"

#: umc/python/diagnostic/plugins/01_ssh_connection.py:16
msgid "SSH connection to UCS server failed!"
msgstr "SSH-Verbindung zu anderem UCS Server fehlgeschlagen!"

#: umc/python/diagnostic/plugins/45_heimdal_on_samba4_dc.py:46
msgid "Samba 4 KDC running."
msgstr "Samba 4 KDC läuft."

#: umc/python/diagnostic/plugins/32_security_limits.py:14
msgid "Security limits exceeded"
msgstr "Sicherheitslimits überschritten"

#: umc/python/diagnostic/plugins/21_check_join_status.py:59
#, python-brace-format
msgid "See {erroranalysis} or run the join-scripts via {join}."
msgstr ""
"Siehe {erroranalysis} oder führen Sie ausstehende JOIN-Skripte via {join} "
"aus."

#: umc/python/diagnostic/plugins/00_check_server_password.py:167
#, python-brace-format
msgid "See {sdb} for information on manual server password change."
msgstr ""
"Siehe {sdb} für weitere Informationen für einen manuellen Tausch des "
"Passwords für das Rechnerkonto."

#: umc/python/diagnostic/plugins/00_check_server_password.py:174
msgid "Set server/password/change=True"
msgstr "Setze server/password/change=True"

#: umc/python/diagnostic/plugins/00_check_server_password.py:180
msgid "Set server/password/interval=21"
msgstr "Setze server/password/interval=21"

#: umc/python/diagnostic/plugins/30_disk_usage.py:129
msgid "Some disks are nearly full:"
msgstr "Einige Festplatten sind beinahe voll:"

#: umc/python/diagnostic/__init__.py:280
msgid "Test again"
msgstr "Erneut testen"

#: umc/python/diagnostic/plugins/43_connectors4_rejects.py:134
msgid ""
"The UCR variable {variable!r} is unset, but necessary for the S4 Connector."
msgstr ""
"Die UCR Variable {variable!r} ist nicht gesetzt, aber notwendig für den S4 "
"Connector."

#: umc/python/diagnostic/plugins/22_kdc_service.py:59
msgid "The check for the KDC reachability was succesful."
msgstr "Erreichbarkeitstest der KDCs war erfolgreich."

#: umc/python/diagnostic/plugins/21_check_join_status.py:41
msgid "The check for the join status was succsesful."
msgstr "Die Überprüfung des Domänenbeitritts war erfolgreich."

#: umc/python/diagnostic/plugins/54_sources_list_check.py:103
msgid "The error might be fixable by regenerating the sources.list."
msgstr ""
"Dieser Fehler könnte durch eine erneute Generierung der Source-Listen "
"behoben werden."

#: umc/python/diagnostic/plugins/50_check_ucr_templates.py:54
msgid "The files should be checked for differences."
msgstr "Die Dateien sollten auf Unterschiede geprüft werden."

#: umc/python/diagnostic/plugins/23_check_update_sites.py:77
msgid "The following FQDNs were not resolvable:"
msgstr "Die folgenden FQDNs waren nicht auflösbar:"

#: umc/python/diagnostic/plugins/22_kdc_service.py:309
msgid "The following KDCs were unreachable: {}"
msgstr "Die folgenden KDCs waren nicht erreichbar: {}"

#: umc/python/diagnostic/plugins/50_check_ucr_templates.py:52
msgid "The following UCR files are modified locally."
msgstr "Die folgenden UCR Vorlagen wurden lokal verändert."

#: umc/python/diagnostic/plugins/01_ssh_connection.py:52
msgid ""
"The following list shows the affected remote servers and the reason for the "
"failed ssh connection:"
msgstr ""
"Die folgende Liste zeigt die betroffenen entfernten Rechner und den Grund "
"für die fehlgeschlagene SSH-Verbindung."

#: umc/python/diagnostic/plugins/51_hostname_check.py:74
#, python-brace-format
msgid "The following non-compliant hostnames have been found: {hostnames}."
msgstr ""
"Die folgenden nicht konformen Rechnernamen wurden gefunden: {hostnames}."

#: umc/python/diagnostic/plugins/10_gateway.py:13
#, python-format
msgid ""
"The gateway %r could not be reached. Please make sure the gateway and "
"related network settings are correctly configured by using the {setup:"
"network}."
msgstr ""
"Das gateway %r konnte nicht erreicht werden. Bitte durch Benutzung des "
"{setup:network} sicherstellen, dass Gateway- und zusammengehörige "
"Netzwerkeinstellungen korrekt konfiguriert sind."

#: umc/python/diagnostic/plugins/12_proxy.py:69
msgid ""
"The hostname of the proxy could not be resolved. May check your DNS "
"configuration."
msgstr ""
"Der Rechnername des Proxies konnte nicht aufgelöst werden. Bitte DNS-"
"Konfiguration überprüfen."

#: umc/python/diagnostic/plugins/32_security_limits.py:61
msgid "The limits have been adjusted to the suggested value."
msgstr "Die Limits wurden auf die empfohlenen Werte erhöht."

#: umc/python/diagnostic/plugins/11_nameserver.py:43
#, python-format
msgid "The nameserver %(nameserver)s (UCR variable %(var)r) is not responsive:"
msgstr ""
"Der Nameserver %(nameserver)s (UCR Variable %(var)r) ist nicht ansprechbar:"

#: umc/python/diagnostic/plugins/53_package_status.py:13
#, python-format
msgid "The package status of %s packages is corrupt."
msgstr "Der Paketstatus von %s Paketen ist korrupt."

#: umc/python/diagnostic/plugins/12_proxy.py:67
#, python-format
msgid ""
"The proxy host could not be reached. Make sure that hostname (%(hostname)r) "
"and port (%(port)r) are correctly set up."
msgstr ""
"Der Proxy-Host konnte nicht erreicht werden. Bitte sicherstellen, dass "
"Rechnername (%(hostname)r) und Port (%(port)r) korrekt eingestellt sind."

#: umc/python/diagnostic/plugins/12_proxy.py:84
#, python-format
msgid ""
"The proxy server is reachable but the HTTP response status code (%d) does "
"not indicate success."
msgstr ""
"Der Proxy-Server ist erreichbar aber der HTTP-Antwort-Status-Code (%d) "
"besagt keinen Erfolg."

#: umc/python/diagnostic/plugins/32_security_limits.py:17
msgid ""
"The security limits (e.g. for max_open_files) are currently not configured "
"properly."
msgstr ""
"Die Sicherheitslimits (z.B. für max_open_files) sind derzeit nicht geeignet "
"eingestellt."

#: umc/python/diagnostic/plugins/12_proxy.py:71
#, python-format
msgid ""
"The server did not respond within %d seconds. Please check your network "
"configuration."
msgstr ""
"Der Server antwortete nicht innerhalb von %d Sekunden. Bitte "
"Netzwerkeinstellungen überprüfen."

#: umc/python/diagnostic/plugins/01_ssh_connection.py:51
msgid "The ssh connection to at least one other UCS server failed. "
msgstr ""
"Die SSH-Verbindung zu mindestens einem anderen UCS Server ist "
"fehlgeschlagen. "

#: umc/python/diagnostic/plugins/01_ssh_connection.py:55
msgid ""
"The ssh host key of the remote server has changed (maybe the host was "
"reinstalled). "
msgstr ""
"Der SSH Host-Key des entfernten Rechners hat sich geändert (vielleicht wurde "
"der Rechner neu installiert). "

#: umc/python/diagnostic/plugins/10_gateway.py:28
msgid "There is no gateway configured."
msgstr "Es ist kein Gateway eingerichtet."

#: umc/python/diagnostic/plugins/12_proxy.py:16
msgid ""
"There was an error using the proxy server. The {setup:network} can be used "
"to change the proxy configuration.\n"
msgstr ""
"Es gab einen Fehler beim Benutzen des Proxy-Servers. Das {setup:network} "
"kann zur Veränderung der Proxy-Konfiguration genutzt werden.\n"

#: umc/python/diagnostic/plugins/32_security_limits.py:18
msgid ""
"This can cause several different serious problems (e.g. the login at samba "
"servers may be impossible, file operations (copy, move) on shares can fail, "
"etc.)"
msgstr ""
"Dies kann mehrere verschiedene ernsthafte Probleme verursachen (z.B. Login "
"an Samba-Servern unmöglich, Dateioperationen (Kopieren, Verschieben) auf "
"Freigaben kann fehlschlagen, uvm.)"

#: umc/python/diagnostic/plugins/45_heimdal_on_samba4_dc.py:76
msgid ""
"This is a Samba 4 DC, but `samba-tool processes` reports no `kdc_server`."
msgstr ""
"Dies ist ein Samba 4 DC, aber `samba-tool processes` zeigt keinen "
"`kdc_server` an."

#: umc/python/diagnostic/plugins/52_mail_acl_sync.py:306
msgid "This is not necessarily a problem, if the the ACL got changed via IMAP."
msgstr ""
"Dies ist nicht notwendigerweise ein Problem, wenn die ACL Einträge per IMAP "
"geändert wurden."

#: umc/python/diagnostic/plugins/45_heimdal_on_samba4_dc.py:77
msgid "This may be, because Heimdal KDC seems to be running."
msgstr "Dies mag daher kommen, dass Heimdal KDC läuft."

#: umc/python/diagnostic/plugins/45_heimdal_on_samba4_dc.py:78
msgid "This may be, because `kerberos/autostart` is not disabled."
msgstr ""
"Dies mag daher kommen, dass `kerberos/autostart` nicht deaktiviert ist."

#: umc/python/diagnostic/plugins/51_hostname_check.py:75
msgid "This may lead to DNS problems."
msgstr "Dies kann zu DNS Problemen führen."

#: umc/python/diagnostic/plugins/03_check_notifier_replication.py:80
msgid "This might indicate an error or still processing transactions."
msgstr ""
"Dies mag auf einen Fehler oder noch ausstehende Transaktionen hinweisen."

#: umc/python/diagnostic/plugins/12_proxy.py:85
#, python-format
msgid ""
"This warning might be harmless. Nevertheless make sure the authentication "
"credentials (if any) are correct and the proxy server ACLs do not forbid "
"requests to %s."
msgstr ""
"Diese Warnung könnte harmlos sein. Trotzdem sollte sichergestellt werden, "
"dass Authentifikations-Zugangsdaten (falls existierend) korrekt sind und die "
"ACL's des Proxy-Servers nicht verbieten, Anfragen an %s zu stellen."

#: umc/python/diagnostic/plugins/43_connectors4_rejects.py:148
#, python-brace-format
msgid "UCS DN: {ucs}, S4 DN: {s4}, Filename: {fn}"
msgstr "UCS DN: {ucs}, S4 DN: {s4}, Dateiname: {fn}"

#: umc/python/diagnostic/plugins/43_connectors4_rejects.py:145
msgid "UCS rejected:"
msgstr "Nicht synchronisierte UCS Objekte:"

#: umc/python/diagnostic/plugins/00_check_server_password.py:75
msgid "Unable to fix machine password on {}"
msgstr ""
"Nicht im Stande das Password für das Rechnerkonto für {} zu korrigieren."

#: umc/python/diagnostic/plugins/03_check_notifier_replication.py:79
msgid "Univention Directory Notifier ID and the locally stored version differ."
msgstr ""
"Univention Directory Notifier ID und die lokal gespeicherte Version "
"unterscheiden sich."

#: umc/python/diagnostic/plugins/43_connectors4_rejects.py:128
msgid "Univention S4 Connector is not installed."
msgstr "Univention S4 Connector ist nicht installiert."

#: umc/python/diagnostic/plugins/20_check_nameservers.py:53
msgid "Univention Support Database - Bind: zone transfer failed"
msgstr ""

#: umc/python/diagnostic/plugins/23_check_update_sites.py:48
msgid ""
"Univention Support Database - DNS Server on DC does not resolve external "
"names"
msgstr ""

#: umc/python/diagnostic/plugins/43_connectors4_rejects.py:49
msgid "Univention Support Database - How to deal with s4-connector rejects"
msgstr ""

#: umc/python/diagnostic/plugins/00_check_server_password.py:57
msgid "Univention Support Database - Manually trigger server password change"
msgstr ""

#: umc/python/diagnostic/plugins/02_certificate_check.py:57
msgid "Univention Support Database - Renewing the TLS/SSL certificates"
msgstr "Univention Support Database - Erneuern der TLS/SSL-Zertifikate"

#: umc/python/diagnostic/plugins/03_check_notifier_replication.py:48
msgid "Univention Support Database - Troubleshooting: Listener-/Notifier"
msgstr ""

#: umc/python/diagnostic/plugins/50_check_ucr_templates.py:53
msgid "Updated versions will be named FILENAME.dpkg-*."
msgstr "Aktualisierte Versionen werden DATEINAME.dpkg-* genannt."

#: umc/python/diagnostic/plugins/44_well_known_sid_check.py:84
msgid ""
"User or group with SID {sid} has name {actual!r}, but should be {expected!r}."
msgstr ""
"Der Nutzer oder die Gruppe mit der SID {sid} hat den Namen {actual!r}, "
"sollte aber {expected!r} sein."

#: umc/python/diagnostic/plugins/44_well_known_sid_check.py:74
msgid ""
"User or group with name {name!r} has sid {actual_sid}, but should be {sid}."
msgstr ""
"Der Nutzer oder die Gruppe mit dem Namen {name!r} hat die SID {actual_sid}, "
"sollte aber {sid} haben."

#: umc/python/diagnostic/plugins/40_samba_tool_dbcheck.py:83
msgid "You can run `samba-tool dbcheck --fix` to fix the issue."
msgstr ""
"Sie können `samba-tool dbcheck --fix` ausführen um die Probleme zu beheben."

#: umc/python/diagnostic/plugins/42_samba_tool_sysvolcheck.py:83
msgid "You can run `samba-tool ntacl sysvolreset` to fix the issue."
msgstr ""
"Sie können `samba-tool ntacl sysvolreset` ausführen um die Probleme zu "
"beheben."

#: umc/python/diagnostic/plugins/30_disk_usage.py:136
msgid "You have configured some high log levels."
msgstr "Sie haben erhöhten Detailgrad für Logmeldungen eingestellt."

#: umc/python/diagnostic/plugins/30_disk_usage.py:113
msgid "You may want to move /var/log to another disk or storage."
msgstr ""
"Sie können /var/log auf eine andere Festplatte oder Speicher verschieben."

#: umc/python/diagnostic/plugins/30_disk_usage.py:115
msgid "You may want to move the local repository to another server."
msgstr "Sie können lokale Repositorys auf einen anderen Server auslagern."

#: umc/python/diagnostic/plugins/30_disk_usage.py:137
#, python-brace-format
msgid "You may want to reset them via {ucr}."
msgstr "Sie können sie per {ucr} zurück setzen."

#: umc/python/diagnostic/plugins/45_heimdal_on_samba4_dc.py:79
#, python-brace-format
msgid "You may want to stop Heimdal KDC and restart Samba via {services}"
msgstr "Sie können Heimdal KDC per {services} stoppen und Samba neu starten."

#: umc/python/diagnostic/plugins/30_disk_usage.py:111
msgid "You may want to uninstall software via {appcenter:appcenter}."
msgstr "Sie können per {appcenter:appcenter} Software entfernen."

#: umc/python/diagnostic/plugins/46_kerberos_ddns_update.py:62
#, python-brace-format
msgid "`kinit` for principal {princ} with keytab {tab} failed."
msgstr ""
"`kinit` für den Principal {princ} mit der Password Tabelle {tab} ist "
"fehlgeschlagen."

#: umc/python/diagnostic/plugins/46_kerberos_ddns_update.py:64
#, python-brace-format
msgid "`kinit` for principal {princ} with password file {file} failed."
msgstr ""
"`kinit` für den Principal {princ} mit der Password Datei {file} ist "
"fehlgeschlagen."

#: umc/python/diagnostic/plugins/46_kerberos_ddns_update.py:75
#, python-brace-format
msgid "`nsupdate` check for domain {domain} failed ({details})."
msgstr "`nsupdate` Prüfung für die Domänne {domain} ist fehlgeschlagen "
"({details})."

#: umc/python/diagnostic/plugins/40_samba_tool_dbcheck.py:88
msgid "`samba-tool dbcheck` found no problems with the local AD database."
msgstr ""
"`samba-tool dbcheck` hat keine Probleme mit der lokalen AD Datenbank "
"gefunden."

#: umc/python/diagnostic/plugins/40_samba_tool_dbcheck.py:79
msgid "`samba-tool dbcheck` returned a problem with the local AD database."
msgstr "`samba-tool dbcheck` fand Probleme mit der lokalen AD Datenbank."

#: umc/python/diagnostic/plugins/41_samba_tool_showrepl.py:151
msgid "`samba-tool drs showrepl` returned a problem with the replication."
msgstr "`samba-tool drs showrepl` gibt ein Problem mit der Replikation zurück."

#: umc/python/diagnostic/plugins/42_samba_tool_sysvolcheck.py:88
msgid "`samba-tool ntacl sysvolcheck` found no problems."
msgstr "`samba-tool ntacl sysvolcheck` hat keine Probleme gefunden."

#: umc/python/diagnostic/plugins/42_samba_tool_sysvolcheck.py:79
msgid "`samba-tool ntacl sysvolcheck` returned a problem with the sysvol ACLs."
msgstr ""
"`samba-tool ntacl sysvolcheck` meldet ein Problem mit den SYSVOL ACL "
"Einträgen."

#: umc/python/diagnostic/plugins/40_samba_tool_dbcheck.py:51
#: umc/python/diagnostic/plugins/42_samba_tool_sysvolcheck.py:53
#, python-brace-format
msgid "`{cmd}` failed."
msgstr "`{cmd}` ist fehlgeschlagen."

#: umc/python/diagnostic/plugins/40_samba_tool_dbcheck.py:53
#: umc/python/diagnostic/plugins/42_samba_tool_sysvolcheck.py:51
#, python-brace-format
msgid "`{cmd}` succeeded."
msgstr "`{cmd}` war erfolgreich."

#: umc/python/diagnostic/plugins/21_check_join_status.py:44
msgid ""
"http://docs.software-univention.de/manual.html#domain:listenernotifier:"
"erroranalysis"
msgstr ""
"http://docs.software-univention.de/handbuch.html#domain:listenernotifier:"
"erroranalysis"

#: umc/python/diagnostic/plugins/02_certificate_check.py:56
msgid "http://sdb.univention.de/1183"
msgstr "http://sdb.univention.de/1000"

#: umc/python/diagnostic/plugins/20_check_nameservers.py:52
msgid "http://sdb.univention.de/1273"
msgstr ""

#: umc/python/diagnostic/plugins/23_check_update_sites.py:47
msgid "http://sdb.univention.de/1298"
msgstr ""

#: umc/python/diagnostic/plugins/51_hostname_check.py:46
msgid "https://tools.ietf.org/html/rfc1123#section-2"
msgstr ""

#: umc/python/diagnostic/plugins/43_connectors4_rejects.py:147
#: umc/python/diagnostic/plugins/43_connectors4_rejects.py:154
msgid "not found"
msgstr "nicht gefunden"

#: umc/python/diagnostic/plugins/22_kdc_service.py:326
msgid "samba/interfaces does not contain lo, 127.0.0.1 or 0.0.0.0."
msgstr "samba/interfaces enthält weder lo noch 127.0.0.1 noch 0.0.0.0."

#: umc/python/diagnostic/plugins/53_package_status.py:28
msgid "some"
msgstr "einigen"
