# This file is auto-generated by the dh-umc tools and should not be edited!
msgid ""
msgstr ""
"Project-Id-Version: univention-management-console-module-diagnostic\n"
"Report-Msgid-Bugs-To: \n"
"POT-Creation-Date: 2018-11-29 15:09+0100\n"
"PO-Revision-Date: \n"
"Last-Translator: Univention GmbH <packages@univention.de>\n"
"Language-Team: Univention GmbH <packages@univention.de>\n"
"Language: de\n"
"MIME-Version: 1.0\n"
"Content-Type: text/plain; charset=UTF-8\n"
"Content-Transfer-Encoding: 8bit\n"

#: 00_check_server_password.py:52
msgid "Check machine password"
msgstr "Password für das Rechnerkonto testen"

#: 00_check_server_password.py:53
msgid "Authentication with machine password against LDAP successful."
msgstr "Authentifizierung mit dem Password für das Rechnerkonto erfolgreich."

#: 00_check_server_password.py:57
msgid "Univention Support Database - Manually trigger server password change"
msgstr ""

#: 00_check_server_password.py:75
msgid "Unable to fix machine password on {}"
msgstr ""
"Nicht im Stande das Password für das Rechnerkonto für {} zu korrigieren."

#: 00_check_server_password.py:117
msgid "Calling /usr/lib/univention-server/server_password_change failed."
msgstr ""
"Aufruf von /usr/lib/univention-server/server_password_change ist "
"fehlgeschlagen."

#: 00_check_server_password.py:118
#, python-brace-format
msgid "Please see {sdb} for more information."
msgstr "Siehe {sdb} für weitere Informationen."

#: 00_check_server_password.py:153
msgid "Fix machine password"
msgstr "Korrigiere Password für das Rechnerkonto"

#: 00_check_server_password.py:158
msgid "Authentication against the local LDAP failed with the machine password."
msgstr ""
"Authentifizierung gegen das lokale LDAP mit dem Password für das "
"Rechnerkonto ist fehlgeschlagen."

#: 00_check_server_password.py:162
msgid ""
"Authentication against the master LDAP failed with the machine password."
msgstr ""
"Authentifizierung gegen das Master LDAP mit dem Password für das "
"Rechnerkonto ist fehlgeschlagen."

#: 00_check_server_password.py:171
msgid ""
"Note that password rotation is disabled via the UCR variable server/password/"
"change."
msgstr ""
"Beachten Sie, dass die Passwordrotation durch die UCR Variable server/"
"password/change deaktiviert ist."

#: 00_check_server_password.py:172
msgid "Note that server/password/interval is set to {}."
msgstr "Beachten Sie, dass server/password/interval auf {} gesetzt ist."

#: 00_check_server_password.py:175
#, python-brace-format
msgid "See {sdb} for information on manual server password change."
msgstr ""
"Siehe {sdb} für weitere Informationen für einen manuellen Tausch des "
"Passwords für das Rechnerkonto."

#: 00_check_server_password.py:182
msgid "Set server/password/change=True"
msgstr "Setze server/password/change=True"

#: 00_check_server_password.py:188
msgid "Set server/password/interval=21"
msgstr "Setze server/password/interval=21"

#: 01_ssh_connection.py:18
msgid "SSH connection to UCS server failed!"
msgstr "SSH-Verbindung zu anderem UCS Server fehlgeschlagen!"

#: 01_ssh_connection.py:63
msgid "The ssh connection to at least one other UCS server failed. "
msgstr ""
"Die SSH-Verbindung zu mindestens einem anderen UCS Server ist "
"fehlgeschlagen. "

#: 01_ssh_connection.py:64
msgid ""
"The following list shows the affected remote servers and the reason for the "
"failed ssh connection:"
msgstr ""
"Die folgende Liste zeigt die betroffenen entfernten Rechner und den Grund "
"für die fehlgeschlagene SSH-Verbindung."

#: 01_ssh_connection.py:66
msgid "Host key for server does not match"
msgstr "SSH Host-Key des Servers stimmt nicht überein"

#: 01_ssh_connection.py:67
msgid ""
"The ssh host key of the remote server has changed (maybe the host was "
"reinstalled). "
msgstr ""
"Der SSH Host-Key des entfernten Rechners hat sich geändert (vielleicht wurde "
"der Rechner neu installiert). "

#: 01_ssh_connection.py:68
#, python-format
msgid ""
"Please repair the host key of the remote server in /root/.ssh/known_hosts on "
"%(fqdn)s."
msgstr ""
"Der SSH Host-Key in /root/.ssh/known_hosts des entfernten Rechners muss auf "
"%(fqdn)s repariert werden."

#: 01_ssh_connection.py:70
msgid "Machine authentication failed"
msgstr "Authentifizierung mit dem Maschinen-Konto ist fehlgeschlagen"

#: 01_ssh_connection.py:71
#, python-format
msgid ""
"Login to the remote server with the uid %(uid)s and the password from /etc/"
"machine.secret failed. "
msgstr ""
"Der Login auf dem entfernten Rechner mit der uid %(uid)s und dem Passwort "
"aus /etc/machine.secret is fehlgeschlagen. "

#: 01_ssh_connection.py:72
msgid ""
"Please check /var/log/auth.log on the remote server for further information."
msgstr ""
"Bitte prüfen Sie /var/log/auth.log auf dem entfernten Rechner für weitere "
"Informationen."

#: 02_certificate_check.py:51
msgid "Check validity of SSL certificates"
msgstr "Überprüfe Gültigkeit der SSL Zertifikate"

#: 02_certificate_check.py:52
msgid "All SSL certificates valid."
msgstr "Alle SSL Zertifikate sind gültig."

#: 02_certificate_check.py:55
msgid "http://sdb.univention.de/1183"
msgstr "http://sdb.univention.de/1000"

#: 02_certificate_check.py:56
msgid "Univention Support Database - Renewing the TLS/SSL certificates"
msgstr "Univention Support Database - Erneuern der TLS/SSL-Zertifikate"

#: 02_certificate_check.py:75
msgid "Certificate {path!r} will expire in {days} days."
msgstr "Zertifikat {path!r} wird in {days} Tagen ablaufen."

#: 02_certificate_check.py:86
msgid "Found not yet valid certificate {path!r}."
msgstr "Noch nicht gültiges Zertifikat {path!r} gefunden."

#: 02_certificate_check.py:92
msgid "Found expired certificate {path!r}."
msgstr "Abgelaufenes Zertifikat {path!r} gefunden."

#: 02_certificate_check.py:103
msgid ""
"Found invalid certificate {path!r}:\n"
"{message}"
msgstr ""
"Ungültiges Zertifikat {path!r} gefunden:\n"
"{message}"

#: 02_certificate_check.py:105
msgid "Found invalid certificate {path!r}."
msgstr "Ungültiges Zertifikat {path!r} gefunden."

#: 02_certificate_check.py:114
msgid "Found malformed certificate {path!r}."
msgstr "Korruptes Zertifikat {path!r} gefunden."

#: 02_certificate_check.py:295
#, python-brace-format
msgid "Please see {sdb} on how to renew certificates."
msgstr "Siehe {sdb} für Informationen zum Erneuern von Zertifikaten."

#: 03_check_notifier_replication.py:41
msgid "Check for problems with UDN replication"
msgstr "Überprüfe Probleme mit der UDN Replikation"

#: 03_check_notifier_replication.py:42
msgid "No problems found with UDN replication."
msgstr "Keine Prolbleme mit der UDN Replikation gefunden."

#: 03_check_notifier_replication.py:47
msgid "Univention Support Database - Troubleshooting: Listener-/Notifier"
msgstr ""

#: 03_check_notifier_replication.py:72
msgid "Error retrieving notifier ID from the UDN."
msgstr "Fehler beim Abrufen der letzten Transaktions ID vom UDN."

#: 03_check_notifier_replication.py:79
msgid "Univention Directory Notifier ID and the locally stored version differ."
msgstr ""
"Univention Directory Notifier ID und die lokal gespeicherte Version "
"unterscheiden sich."

#: 03_check_notifier_replication.py:80
msgid "This might indicate an error or still processing transactions."
msgstr ""
"Dies mag auf einen Fehler oder noch ausstehende Transaktionen hinweisen."

#: 04_saml_certificate_check.py:52
msgid "SAML certificate verification failed!"
msgstr "Überprüfung der SAML-Zertifikate fehlgeschlagen!"

#: 04_saml_certificate_check.py:98
msgid "The certificate of the SAML identity provider does not match."
msgstr "Das Zertifikat des SAML Identity Providers stimmt nicht überein."

#: 04_saml_certificate_check.py:119
msgid "The certificate of the SAML service provider does not match."
msgstr "Das Zertifikat des SAML Service Providers stimmt nicht überein."

#: 10_gateway.py:11
msgid "Gateway is not reachable"
msgstr "Gateway ist nicht erreichbar"

#: 10_gateway.py:13
#, python-format
msgid ""
"The gateway %r could not be reached. Please make sure the gateway and "
"related network settings are correctly configured by using the {setup:"
"network}."
msgstr ""
"Das gateway %r konnte nicht erreicht werden. Bitte durch Benutzung des "
"{setup:network} sicherstellen, dass Gateway- und zusammengehörige "
"Netzwerkeinstellungen korrekt konfiguriert sind."

#: 10_gateway.py:14
msgid "If these settings are correct the problem relies in the gateway itself:"
msgstr ""
"Wenn diese Einstellungen richtig sind liegt das Problem im Gateway selbst:"

#: 10_gateway.py:15
msgid "Make sure the hardware of the gateway device is working properly."
msgstr ""
"Stellen Sie sicher, dass die Hardware des Gateway-Geräts korrekt "
"funktioniert."

#: 10_gateway.py:31
msgid "There is no gateway configured."
msgstr "Es ist kein Gateway eingerichtet."

#: 11_nameserver.py:13
msgid "Nameserver(s) are not responsive"
msgstr "Nameserver sind nicht ansprechbar"

#: 11_nameserver.py:15
#, python-format
msgid "%d of the configured nameservers are not responding to DNS queries."
msgstr "%d der konfigurierten Nameserver anworten nicht auf DNS-Anfragen."

#: 11_nameserver.py:16
msgid ""
"Please make sure the DNS settings in the {setup:network} are correctly set "
"up."
msgstr ""
"Bitte sicherstellen, dass die DNS-Einstellungen in {setup:network} korrekt "
"konfiguriert sind."

#: 11_nameserver.py:17
msgid ""
"If the problem persists make sure the nameserver is connected to the network "
"and the forwarders are able to reach the internet (www.univention.de)."
msgstr ""
"Falls das Problem bestehen bleibt stellen Sie sicher, dass der Nameserver "
"mit dem Netzwerk verbunden ist und die DNS-Forwarder das Internet erreichen "
"können (www.univention.de)."

#: 11_nameserver.py:45
#, python-format
msgid "The nameserver %(nameserver)s (UCR variable %(var)r) is not responsive:"
msgstr ""
"Der Nameserver %(nameserver)s (UCR Variable %(var)r) ist nicht ansprechbar:"

#: 11_nameserver.py:48
msgid "A timeout occurred while reaching the nameserver (is it online?)."
msgstr ""
"Eine Zeitüberschreitung trat beim Erreichen des Nameservers auf (ist er "
"online?)."

#: 12_proxy.py:14
msgid "Proxy server failure"
msgstr "Proxy-Server-Fehler"

#: 12_proxy.py:15
msgid ""
"There was an error using the proxy server. The {setup:network} can be used "
"to change the proxy configuration.\n"
msgstr ""
"Es gab einen Fehler beim Benutzen des Proxy-Servers. Das {setup:network} "
"kann zur Veränderung der Proxy-Konfiguration genutzt werden.\n"

#: 12_proxy.py:69
#, python-format
msgid ""
"The proxy host could not be reached. Make sure that hostname (%(hostname)r) "
"and port (%(port)r) are correctly set up."
msgstr ""
"Der Proxy-Host konnte nicht erreicht werden. Bitte sicherstellen, dass "
"Rechnername (%(hostname)r) und Port (%(port)r) korrekt eingestellt sind."

#: 12_proxy.py:71
msgid ""
"The hostname of the proxy could not be resolved. May check your DNS "
"configuration."
msgstr ""
"Der Rechnername des Proxies konnte nicht aufgelöst werden. Bitte DNS-"
"Konfiguration überprüfen."

#: 12_proxy.py:73
#, python-format
msgid ""
"The server did not respond within %d seconds. Please check your network "
"configuration."
msgstr ""
"Der Server antwortete nicht innerhalb von %d Sekunden. Bitte "
"Netzwerkeinstellungen überprüfen."

#: 12_proxy.py:87
#, python-format
msgid ""
"The proxy server is reachable but the HTTP response status code (%d) does "
"not indicate success."
msgstr ""
"Der Proxy-Server ist erreichbar aber der HTTP-Antwort-Status-Code (%d) "
"besagt keinen Erfolg."

#: 12_proxy.py:88
#, python-format
msgid ""
"This warning might be harmless. Nevertheless make sure the authentication "
"credentials (if any) are correct and the proxy server ACLs do not forbid "
"requests to %s."
msgstr ""
"Diese Warnung könnte harmlos sein. Trotzdem sollte sichergestellt werden, "
"dass Authentifikations-Zugangsdaten (falls existierend) korrekt sind und die "
"ACL's des Proxy-Servers nicht verbieten, Anfragen an %s zu stellen."

#: 20_check_nameservers.py:49
msgid "Check nameserver entries on DNS zones"
msgstr "Überprüfe die Nameserver Einträge der DNS Zonen"

#: 20_check_nameservers.py:53
msgid "http://sdb.univention.de/1273"
msgstr ""

#: 20_check_nameservers.py:54
msgid "Univention Support Database - Bind: zone transfer failed"
msgstr ""

#: 20_check_nameservers.py:74
#, python-brace-format
msgid "Found no host record (A/AAAA record) for nameserver {ns}."
msgstr "Kein Host-Record (A/AAAA record) für Namenserver {ns} gefunden."

#: 20_check_nameservers.py:80
#, python-brace-format
msgid "Found illegal alias record (CNAME record) for nameserver {ns}."
msgstr "Ungültiger Alias-Record (CNAME record) für Namenserver {ns} gefunden."

#: 20_check_nameservers.py:221
msgid "Found errors in the nameserver entries of the following zones."
msgstr ""
"Es wurden Fehler in den Nameserver Einträgen der folgenden Zonen gefunden."

#: 20_check_nameservers.py:222
#, python-brace-format
msgid "Please refer to {sdb} for further information."
msgstr "Siehe {sdb} für weitere Informationen."

#: 20_check_nameservers.py:224
#, python-brace-format
msgid "In forward zone {name} (see {{{link}}}):"
msgstr "In der Forward-Zone {name} (siehe {{{link}}}):"

#: 20_check_nameservers.py:225
#, python-brace-format
msgid "In reverse zone {name} (see {{{link}}}):"
msgstr "In der Reverse-Zone {name} (siehe {{{link}}}):"

#: 21_check_join_status.py:40
msgid "Check join status"
msgstr "Überprüfe den Zustand des Domänenbeitritts"

#: 21_check_join_status.py:41
msgid "The check for the join status was succsesful."
msgstr "Die Überprüfung des Domänenbeitritts war erfolgreich."

#: 21_check_join_status.py:44
msgid ""
"http://docs.software-univention.de/manual.html#domain:listenernotifier:"
"erroranalysis"
msgstr ""
"http://docs.software-univention.de/handbuch.html#domain:listenernotifier:"
"erroranalysis"

#: 21_check_join_status.py:45
msgid "Manual: Analysis of listener/notifier problems"
msgstr "Handbuch: Analyse von Listener/Notifier-Problemen"

#: 21_check_join_status.py:55
msgid ""
"\"univention-check-join-status\" returned a problem with the domain join."
msgstr ""
"\"univention-check-join-status\" gab einen Fehler mit dem Domänenbeitritt "
"zurück."

#: 21_check_join_status.py:60
#, python-brace-format
msgid "See {erroranalysis} or run the join-scripts via {join}."
msgstr ""
"Siehe {erroranalysis} oder führen Sie ausstehende JOIN-Skripte via {join} "
"aus."

#: 22_kdc_service.py:57
msgid "KDC service check"
msgstr "KDC Erreichbarkeit"

#: 22_kdc_service.py:103
msgid "ph "
msgstr ""

#: 22_kdc_service.py:323
msgid "The following KDCs were unreachable: {}"
msgstr "Die folgenden KDCs waren nicht erreichbar: {}"

#: 22_kdc_service.py:341
msgid "samba/interfaces does not contain lo, 127.0.0.1 or 0.0.0.0."
msgstr "samba/interfaces enthält weder lo noch 127.0.0.1 noch 0.0.0.0."

#: 22_kdc_service.py:347
msgid "Add lo to samba/interfaces"
msgstr "Füge lo zu samba/interfaces hinzu"

#: 22_kdc_service.py:350
msgid "Reset kerberos/kdc to 127.0.0.1"
msgstr "Setze kerberos/kdc auf 127.0.0.1 zurück"

#: 22_kdc_service.py:354
msgid "No reachable KDCs were found."
msgstr "Keine erreichbaren KDCs gefunden."

#: 23_check_update_sites.py:42
msgid "Check resolving repository servers"
msgstr "Überprüfe DNS Auflösung der Repository Server"

#: 23_check_update_sites.py:43
msgid "No problems were found while resolving update repositories."
msgstr "Es wurden keine Probleme beim Auflösen der Repository-Server gefunden."

#: 23_check_update_sites.py:46
msgid "http://sdb.univention.de/1298"
msgstr ""

#: 23_check_update_sites.py:47
msgid ""
"Univention Support Database - DNS Server on DC does not resolve external "
"names"
msgstr ""

#: 23_check_update_sites.py:80
msgid "The following FQDNs were not resolvable:"
msgstr "Die folgenden FQDNs waren nicht auflösbar:"

#: 23_check_update_sites.py:84
#, python-brace-format
msgid "Please see {sdb} for troubleshooting DNS problems."
msgstr "Siehe {sdb} für Problemhilfe bei DNS Problemen."

#: 30_disk_usage.py:42
msgid "Check free disk space"
msgstr "Überprüfe freien Festplatten Platz"

#: 30_disk_usage.py:43
msgid "Enough free disk space available."
msgstr "Außreichend freier Festplatten Platz vorhanden."

#: 30_disk_usage.py:112
msgid "You may want to uninstall software via {appcenter:appcenter}."
msgstr "Sie können per {appcenter:appcenter} Software entfernen."

#: 30_disk_usage.py:114
msgid "You may want to move /var/log to another disk or storage."
msgstr ""
"Sie können /var/log auf eine andere Festplatte oder Speicher verschieben."

#: 30_disk_usage.py:116
msgid "You may want to move the local repository to another server."
msgstr "Sie können lokale Repositorys auf einen anderen Server auslagern."

#: 30_disk_usage.py:121
#, python-format
msgid "- Disk for mountpoint %(mp)s is %(pc)s%% full."
msgstr "- Festplatte für Moint Point %(mp)s ist %(pc)s%% voll."

#: 30_disk_usage.py:130
msgid "Some disks are nearly full:"
msgstr "Einige Festplatten sind beinahe voll:"

#: 30_disk_usage.py:137
msgid "You have configured some high log levels."
msgstr "Sie haben erhöhten Detailgrad für Logmeldungen eingestellt."

#: 30_disk_usage.py:138
#, python-brace-format
msgid "You may want to reset them via {ucr}."
msgstr "Sie können sie per {ucr} zurück setzen."

#: 31_file_permissions.py:48
msgid "Check file permissions"
msgstr "Überprüfe Datei Berechtigungen"

#: 31_file_permissions.py:49 54_sources_list_check.py:44
msgid "All files ok."
msgstr "Alle Dateien in Ordnung."

#: 31_file_permissions.py:60
msgid "File {path!r} does not exist."
msgstr "Datei {path!r} existiert nicht."

#: 31_file_permissions.py:70
msgid "File {path!r} has owner {actual!r} while {expected!r} was expected."
msgstr ""
"Datei {path!r} hat den Besitzer {actual!r}, während {expected!r} erwartet "
"war."

#: 31_file_permissions.py:83
msgid "File {path!r} has mode {actual:o}, {expected:o} was expected."
msgstr "Datei {path!r} hat Datei-Modus {actual:o}, {expected:o} war erwartet."

#: 32_security_limits.py:14
msgid "Security limits exceeded"
msgstr "Sicherheitslimits überschritten"

#: 32_security_limits.py:17
msgid ""
"The security limits (e.g. for max_open_files) are currently not configured "
"properly."
msgstr ""
"Die Sicherheitslimits (z.B. für max_open_files) sind derzeit nicht geeignet "
"eingestellt."

#: 32_security_limits.py:18
msgid ""
"This can cause several different serious problems (e.g. the login at samba "
"servers may be impossible, file operations (copy, move) on shares can fail, "
"etc.)"
msgstr ""
"Dies kann mehrere verschiedene ernsthafte Probleme verursachen (z.B. Login "
"an Samba-Servern unmöglich, Dateioperationen (Kopieren, Verschieben) auf "
"Freigaben kann fehlschlagen, uvm.)"

#: 32_security_limits.py:19
#, python-brace-format
msgid ""
"It is suggested to increase the security limits either manually by using "
"{ucr} or to automatically adjust them to the suggested limits:"
msgstr ""
"Es ist empfohlen, die Sicherheitslimits entweder manuell durch benutzen des "
"{ucr} oder durch automatische Anpassung auf die empfohlenen Limits zu "
"erhöhen."

#: 32_security_limits.py:31
msgid "Adjust to suggested limits"
msgstr "An vorgeschlagene Limits anpassen"

#: 32_security_limits.py:63
msgid "The limits have been adjusted to the suggested value."
msgstr "Die Limits wurden auf die empfohlenen Werte erhöht."

#: 40_samba_tool_dbcheck.py:39
msgid "Check local AD database for errors"
msgstr "Teste die lokale AD Datenbank auf Fehler"

#: 40_samba_tool_dbcheck.py:40 41_samba_tool_showrepl.py:54
#: 42_samba_tool_sysvolcheck.py:41
msgid "No errors found."
msgstr "Keine Fehler gefunden."

#: 40_samba_tool_dbcheck.py:53
#, python-brace-format
msgid "Output of `{cmd}`:"
msgstr "Ausgabe von `{cmd}`:"

#: 40_samba_tool_dbcheck.py:74
msgid "Run `samba-tool dbcheck --fix --cross-ncs --yes`"
msgstr "Führe `samba-tool dbcheck --fix --cross-ncs --yes` aus"

#: 40_samba_tool_dbcheck.py:80
msgid "`samba-tool dbcheck` found an error in the local AD database."
msgstr "`samba-tool dbcheck` fand einen Fehler in der lokalen AD Datenbank."

#: 40_samba_tool_dbcheck.py:84
msgid "You can run `samba-tool dbcheck --fix` to fix the issue."
msgstr ""
"Sie können `samba-tool dbcheck --fix` ausführen um die Probleme zu beheben."

#: 40_samba_tool_dbcheck.py:89
msgid "`samba-tool dbcheck` found no errors in the local AD database."
msgstr ""
"`samba-tool dbcheck` hat keine Fehler in der lokalen AD Datenbank gefunden."

#: 41_samba_tool_showrepl.py:53
msgid "Check Samba replication status for errors"
msgstr "Überprüfe den Samba Replikations Status"

#: 41_samba_tool_showrepl.py:131
msgid "Inbound {nc!r}: error during DRS replication from {source} ({estring})"
msgstr ""
"In eingehend {nc!r}: Fehler während der DRS Replikation von {source} "
"({estring})."

#: 41_samba_tool_showrepl.py:139
msgid "Outbound {nc!r}: error during DRS replication to {source} ({estring})"
msgstr ""
"In ausgehend {nc!r}: Fehler während der DRS Replikation nach {source} "
"({estring})."

#: 41_samba_tool_showrepl.py:152
msgid "`samba-tool drs showrepl` returned a problem with the replication."
msgstr "`samba-tool drs showrepl` gibt ein Problem mit der Replikation zurück."

#: 42_samba_tool_sysvolcheck.py:40
msgid "Check Samba sysvol ACLs for errors"
msgstr "Überprüfe die Samba SYSVOL ACL Einträge auf Fehler"

#: 42_samba_tool_sysvolcheck.py:54
#, python-brace-format
msgid "`{cmd}` succeeded."
msgstr "`{cmd}` war erfolgreich."

#: 42_samba_tool_sysvolcheck.py:57
#, python-brace-format
msgid "`{cmd}` failed."
msgstr "`{cmd}` ist fehlgeschlagen."

#: 42_samba_tool_sysvolcheck.py:79
msgid "Run `samba-tool ntacl sysvolreset`"
msgstr "Führe `samba-tool ntacl sysvolreset` aus"

#: 42_samba_tool_sysvolcheck.py:85
msgid "`samba-tool ntacl sysvolcheck` returned a problem with the sysvol ACLs."
msgstr ""
"`samba-tool ntacl sysvolcheck` meldet ein Problem mit den SYSVOL ACL "
"Einträgen."

#: 42_samba_tool_sysvolcheck.py:87
msgid "Running 'samba-tool ntacl sysvolreset' may fix the issue"
msgstr ""
"Das Durchführen von samba-tool ntacl sysvolreset kann helfen, das Problem zu "
"beheben."

#: 42_samba_tool_sysvolcheck.py:103
msgid "`samba-tool ntacl sysvolcheck` found no problems."
msgstr "`samba-tool ntacl sysvolcheck` hat keine Probleme gefunden."

#: 43_connectors4_rejects.py:44
msgid "S4 Connector rejects"
msgstr "Nicht synchronisierte S4 Connector Objekte"

#: 43_connectors4_rejects.py:45
msgid "No S4 Connector rejects were found."
msgstr "Keine nicht synchronisierten S4 Connector Objekte gefunden."

#: 43_connectors4_rejects.py:49
msgid "Univention Support Database - How to deal with s4-connector rejects"
msgstr ""

#: 43_connectors4_rejects.py:131
msgid "Univention S4 Connector is not installed."
msgstr "Univention S4 Connector ist nicht installiert."

#: 43_connectors4_rejects.py:137
msgid ""
"The UCR variable {variable!r} is unset, but necessary for the S4 Connector."
msgstr ""
"Die UCR Variable {variable!r} ist nicht gesetzt, aber notwendig für den S4 "
"Connector."

#: 43_connectors4_rejects.py:145
#, python-brace-format
msgid ""
"Found {ucs} UCS rejects and {s4} S4 rejects. See {{sdb}} for more "
"information."
msgstr ""
"{ucs} nicht synchronisierte UCS Objekte und {s4} nicht synchronisierte S4 "
"Objekte. Weitere Hinweise finden Sie unter {{sdb}}."

#: 43_connectors4_rejects.py:149
msgid "UCS rejected:"
msgstr "Nicht synchronisierte UCS Objekte:"

#: 43_connectors4_rejects.py:151 43_connectors4_rejects.py:158
msgid "not found"
msgstr "nicht gefunden"

#: 43_connectors4_rejects.py:152
#, python-brace-format
msgid "UCS DN: {ucs}, S4 DN: {s4}, Filename: {fn}"
msgstr "UCS DN: {ucs}, S4 DN: {s4}, Dateiname: {fn}"

#: 43_connectors4_rejects.py:156
msgid "S4 rejected:"
msgstr "Nicht synchronisierte S4 Objekte:"

#: 43_connectors4_rejects.py:159
#, python-brace-format
msgid "S4 DN: {s4}, UCS DN: {ucs}"
msgstr ""

#: 44_well_known_sid_check.py:45
msgid "Check well known SIDs"
msgstr "Überprüfe 'Well Known' SIDs"

#: 44_well_known_sid_check.py:46
msgid "All SIDs exist and names are consistent."
msgstr "Alle SIDs existieren und die Namen sind konsistent."

#: 44_well_known_sid_check.py:64
msgid "No user or group with SID {sid} found, expected {expected!r}."
msgstr ""
"Kein Nutzer oder keine Gruppe mit SID {sid} gefunden, {expected!r} war "
"erwartet."

#: 44_well_known_sid_check.py:74
msgid ""
"User or group with name {name!r} has sid {actual_sid}, but should be {sid}."
msgstr ""
"Der Nutzer oder die Gruppe mit dem Namen {name!r} hat die SID {actual_sid}, "
"sollte aber {sid} haben."

#: 44_well_known_sid_check.py:84
msgid ""
"User or group with SID {sid} has name {actual!r}, but should be {expected!r}."
msgstr ""
"Der Nutzer oder die Gruppe mit der SID {sid} hat den Namen {actual!r}, "
"sollte aber {expected!r} sein."

#: 45_heimdal_on_samba4_dc.py:45
msgid "Check Heimdal KDC on Samba 4 DC"
msgstr "Überprüfe Heimdal KDC auf Samba 4 DC"

#: 45_heimdal_on_samba4_dc.py:46
msgid "Samba 4 KDC running."
msgstr "Samba 4 KDC läuft."

#: 45_heimdal_on_samba4_dc.py:77
msgid ""
"This is a Samba 4 DC, but `samba-tool processes` reports no `kdc_server`."
msgstr ""
"Dies ist ein Samba 4 DC, aber `samba-tool processes` zeigt keinen "
"`kdc_server` an."

#: 45_heimdal_on_samba4_dc.py:78
msgid "This may be, because Heimdal KDC seems to be running."
msgstr "Dies mag daher kommen, dass Heimdal KDC läuft."

#: 45_heimdal_on_samba4_dc.py:79
msgid "This may be, because `kerberos/autostart` is not disabled."
msgstr ""
"Dies mag daher kommen, dass `kerberos/autostart` nicht deaktiviert ist."

#: 45_heimdal_on_samba4_dc.py:80
#, python-brace-format
msgid "You may want to stop Heimdal KDC and restart Samba via {services}"
msgstr "Sie können Heimdal KDC per {services} stoppen und Samba neu starten."

#: 46_kerberos_ddns_update.py:45
msgid "Check kerberos authenticated DNS updates"
msgstr "Überprüfe Kerberos authentifizierte DNS Updates"

#: 46_kerberos_ddns_update.py:46
msgid "No errors occured."
msgstr "Es traten keine Fehler auf."

#: 46_kerberos_ddns_update.py:63
#, python-brace-format
msgid "`kinit` for principal {princ} with keytab {tab} failed."
msgstr ""
"`kinit` für den Principal {princ} mit der Password Tabelle {tab} ist "
"fehlgeschlagen."

#: 46_kerberos_ddns_update.py:65
#, python-brace-format
msgid "`kinit` for principal {princ} with password file {file} failed."
msgstr ""
"`kinit` für den Principal {princ} mit der Password Datei {file} ist "
"fehlgeschlagen."

#: 46_kerberos_ddns_update.py:76
#, python-brace-format
msgid "`nsupdate` check for domain {domain} failed ({details})."
msgstr ""
"`nsupdate` Prüfung für die Domänne {domain} ist fehlgeschlagen ({details})."

#: 46_kerberos_ddns_update.py:165
msgid "Errors occured while running `kinit` or `nsupdate`."
msgstr "Fehler traten auf bei der Ausführung von `kinit` oder `nsupdate`."

#: 50_check_ucr_templates.py:41
msgid "Check for modified UCR templates"
msgstr "Überprüfe veränderte UCR Vorlagen"

#: 50_check_ucr_templates.py:42
msgid "No problems found with modified UCR templates"
msgstr "Keine Probleme mit modifizierten UCR Vorlagen gefunden."

#: 50_check_ucr_templates.py:52
msgid "Errors found by `univention-check-templates`."
msgstr "Es wurden Fehler durch `univention-check-templates` gefunden."

#: 50_check_ucr_templates.py:53
msgid "The following UCR files are modified locally."
msgstr "Die folgenden UCR Vorlagen wurden lokal verändert."

#: 50_check_ucr_templates.py:54
msgid "Updated versions will be named FILENAME.dpkg-*."
msgstr "Aktualisierte Versionen werden DATEINAME.dpkg-* genannt."

#: 50_check_ucr_templates.py:55
msgid "The files should be checked for differences."
msgstr "Die Dateien sollten auf Unterschiede geprüft werden."

#: 51_hostname_check.py:42
msgid "Check hostname RFC compliance"
msgstr "Überprüfe Rechnernamen auf RFC Konformität"

#: 51_hostname_check.py:43
msgid "No non-compliant hostnames found."
msgstr "Keine nicht konformen Rechnernamen gefunden."

#: 51_hostname_check.py:46
msgid "https://tools.ietf.org/html/rfc1123#section-2"
msgstr ""

#: 51_hostname_check.py:47
msgid "RFC 1123 - 2.1 Host Names and Numbers"
msgstr ""

#: 51_hostname_check.py:75
#, python-brace-format
msgid "The following non-compliant hostnames have been found: {hostnames}."
msgstr ""
"Die folgenden nicht konformen Rechnernamen wurden gefunden: {hostnames}."

#: 51_hostname_check.py:76
msgid "This may lead to DNS problems."
msgstr "Dies kann zu DNS Problemen führen."

#: 51_hostname_check.py:77
#, python-brace-format
msgid "Please refer to {rfc1123} for the syntax of host names."
msgstr "Siehe {rfc1123} für die Syntax von Rechnernamen."

#: 52_mail_acl_sync.py:48
msgid "Check IMAP shared folder ACLs"
msgstr "Überprüfe ACL Einträge der globalen IMAP Ordner"

#: 52_mail_acl_sync.py:49
msgid "All shared folder ACLs are in sync with UDM."
msgstr "Alle ACL Einträge der globalen IMAP Ordner stimmen mit UDM überein."

#: 52_mail_acl_sync.py:63
msgid "Mail folder {folder!r} does not exist in IMAP."
msgstr "Globaler IMAP Order {folder!r} existiert nicht in IMAP."

#: 52_mail_acl_sync.py:75
msgid "Multiple ACL entries for {id!r} in UDM."
msgstr "Mehrere ACL Einträge für {id!r} in UDM."

#: 52_mail_acl_sync.py:88
msgid "ACL right for user {id!r} is {udm!r} in UDM, but {imap!r} in IMAP."
msgstr ""
"ACL Berechtigung für den Nutzer {id!r} ist {udm!r} in UDM, aber {imap!r} in "
"IMAP."

#: 52_mail_acl_sync.py:94
msgid "ACL right for group {id!r} is {udm!r} in UDM, but {imap!r} in IMAP."
msgstr ""
"ACL Berechtigung für die Gruppe {id!r} ist {udm!r} in UDM, aber {imap!r} in "
"IMAP."

#: 52_mail_acl_sync.py:236
msgid ""
"Found differences in the ACLs for IMAP shared folders between UDM and IMAP."
msgstr ""
"Es wurde ein Unterschied in den ACL Einträge für die globalen IMAP Ordner "
"zwischen UDM und IMAP gefunden."

#: 52_mail_acl_sync.py:237
msgid "This is not necessarily a problem, if the the ACL got changed via IMAP."
msgstr ""
"Dies ist nicht notwendigerweise ein Problem, wenn die ACL Einträge per IMAP "
"geändert wurden."

#: 52_mail_acl_sync.py:243
#, python-brace-format
msgid "In mail folder {name} (see {{udm:mail/mail}}):"
msgstr "Im globalen Mail Ordner {name} (siehe {{udm:mail/mail}}):"

#: 53_package_status.py:11
msgid "Package status corrupt"
msgstr "Paketstatus korrupt"

#: 53_package_status.py:13
#, python-format
msgid "The package status of %s packages is corrupt."
msgstr "Der Paketstatus von %s Paketen ist korrupt."

#: 53_package_status.py:14
msgid ""
"You may log in to the system as root via ssh and run the command \"dpkg --"
"configure -a\" as an attempt to correct the packages status."
msgstr ""
"Um den Paketstatus zu korrigieren, loggen Sie sich am System per ssh als "
"root ein und führen Sie das Kommando \"dpkg --configure -a\" aus."

#: 53_package_status.py:15
msgid ""
"More information about the cause can be gained by executing \"dpkg --audit\"."
msgstr ""
"Weitere Informationen über die Ursache können durch Ausführen von \"dpkg --"
"audit\" erhalten werden."

#: 53_package_status.py:30
msgid "some"
msgstr "einigen"

#: 54_sources_list_check.py:43
msgid "Check errors in sources.list files"
msgstr "Überprüfe Fehler in den sources.list Dateien"

#: 54_sources_list_check.py:75
msgid "Found exception in {path!r}: {exception}"
msgstr "Fehler in {path!r} gefunden: {exception}"

#: 54_sources_list_check.py:97
msgid "Regenerate sources.list"
msgstr "Source-Listen neu generieren"

#: 54_sources_list_check.py:101
msgid "Please check the files for more details."
msgstr "Überprüfen Sie die Dateien für mehr Details."

#: 54_sources_list_check.py:103
msgid "The error might be fixable by regenerating the sources.list."
msgstr ""
"Dieser Fehler könnte durch eine erneute Generierung der Source-Listen "
"behoben werden."

#: 55_user_migration.py:11
msgid "User objects which are not migrated"
msgstr "Noch nicht migrierte Nutzer Objekte"

#: 55_user_migration.py:13
msgid ""
"With UCS 4.3 the LDAP format of user objects changed. After upgrading the "
"domaincontroller master all user objects are migrated into the new format."
msgstr ""
"Mit UCS 4.3 hat sich das LDAP format von Nutzer Objekten geändert. Nach "
"Upgrade des Domänencontroller Master werden all Nutzer Objekte in das neue "
"Format migriert."

#: 55_user_migration.py:14
msgid ""
"When a user object is created by a system which is not yet on UCS 4.3 it "
"will have the old format. These user objects need to migrated again."
msgstr ""
"Wenn ein Nutzer auf System erstellt wurde, welches noch nicht auf UCS 4.3 "
"ist, wird dieser im alten Format sein. Diese Nutzer Objekte müssen erneut "
"migriert werden."

#: 55_user_migration.py:29
msgid "Migrate user objects"
msgstr "Migriere Nutzer Objekte"

#: 55_user_migration.py:38
#, python-format
msgid "The migration failed: %s"
msgstr "Die Migration schlug fehl: %s"

#: 56_univention_types.py:13
msgid "LDAP objects"
msgstr "LDAP-Objekte"

#: 56_univention_types.py:15
msgid ""
"Several services rely on the attribute \"univentionObjectType\" to search "
"and identify objects in LDAP."
msgstr ""
"Verschiedene Dienste vertrauen auf das Attribut \"univentionObjectType\", um "
"nach Objekten im LDAP zu suchen oder diese zu identifizieren."

#: 56_univention_types.py:16
msgid ""
"Objects that implicitly satisfy the standards of a Univention Object but "
"lack this attribute should be migrated."
msgstr ""
"Objekte, die die Anforderungen eines Univention-Objekts implizit erfüllen, "
"aber dieses Attribut nicht gesetzt haben, sollten migriert werden."

#: 56_univention_types.py:50
msgid "These objects were found:"
msgstr "Diese Objekte wurden gefunden:"

#: 56_univention_types.py:57
#, python-format
msgid "%d objects should be \"%s\""
msgstr "%d Objekte sollten \"%s\" sein"

#: 56_univention_types.py:60
#, python-format
msgid "Migrate %d LDAP objects"
msgstr "Migriere %d LDAP-Objekte"

#~ msgid "All nameserver entries are ok."
#~ msgstr "Alle Nameserver Einträge sind in Ordnung."

#~ msgid "Test again"
#~ msgstr "Erneut testen"

#~ msgid "The check for the KDC reachability was succesful."
#~ msgstr "Erreichbarkeitstest der KDCs war erfolgreich."

#~ msgid "Repair identity provider certificate"
#~ msgstr "Identity Provider-Zertifikat wiederherstellen"

#~ msgid "Repair service provider certificate"
#~ msgstr "Service Provider-Zertifikat wiederherstellen"
